order-book/tests/test-13.out
{"buyOrders": [], "sellOrders": [{"id": 1, "price": 101, "quantity": 20000}]}
{"buyOrders": [{"id": 2, "price": 99, "quantity": 50000}], "sellOrders": [{"id": 1, "price": 101, "quantity": 20000}]}
{"buyOrders": [{"id": 2, "price": 99, "quantity": 50000}], "sellOrders": [{"id": 3, "price": 100, "quantity": 10000}, {"id": 1, "price": 101, "quantity": 20000}]}
{"buyOrders": [{"id": 2, "price": 99, "quantity": 50000}], "sellOrders": [{"id": 3, "price": 100, "quantity": 10000}, {"id": 4, "price": 100, "quantity": 7500}, {"id": 1, "price": 101, "quantity": 20000}]}
{"buyOrders": [{"id": 2, "price": 99, "quantity": 50000}, {"id": 5, "price": 98, "quantity": 25500}], "sellOrders": [{"id": 3, "price": 100, "quantity": 10000}, {"id": 4, "price": 100, "quantity": 7500}, {"id": 1, "price": 101, "quantity": 20000}]}
{"buyOrders": [{"id": 6, "price": 100, "quantity": 10000}, {"id": 2, "price": 99, "quantity": 50000}, {"id": 5, "price": 98, "quantity": 25500}], "sellOrders": [{"id": 1, "price": 101, "quantity": 20000}]}
{"buyOrders": [{"id": 6, "price": 100, "quantity": 10000}, {"id": 2, "price": 99, "quantity": 50000}, {"id": 5, "price": 98, "quantity": 25500}], "sellOrders": [{"id": 1, "price": 101, "quantity": 20000}]}
{"buyOrders": [{"id": 6, "price": 100, "quantity": 9000}, {"id": 2, "price": 99, "quantity": 50000}, {"id": 5, "price": 98, "quantity": 25500}], "sellOrders": [{"id": 1, "price": 101, "quantity": 20000}]}
{"buyOrders": [{"id": 6, "price": 100, "quantity": 9000}, {"id": 9, "price": 100, "quantity": 20000}, {"id": 2, "price": 99, "quantity": 50000}, {"id": 5, "price": 98, "quantity": 25500}], "sellOrders": [{"id": 1, "price": 101, "quantity": 20000}]}
{"buyOrders": [{"id": 6, "price": 100, "quantity": 4000}, {"id": 9, "price": 100, "quantity": 20000}, {"id": 2, "price": 99, "quantity": 50000}, {"id": 5, "price": 98, "quantity": 25500}], "sellOrders": [{"id": 1, "price": 101, "quantity": 20000}]}
{"buyOrderId": 6, "sellOrderId": 3, "price": 100,  "quantity": 10000}
{"buyOrderId": 6, "sellOrderId": 4, "price": 100,  "quantity": 7500}
{"buyOrderId": 6, "sellOrderId": 7, "price": 100,  "quantity": 10000}
{"buyOrderId": 6, "sellOrderId": 8, "price": 100,  "quantity": 10000}
{"buyOrderId": 6, "sellOrderId": 8, "price": 100,  "quantity": 1000}
{"buyOrderId": 6, "sellOrderId": 10, "price": 100,  "quantity": 9000}
{"buyOrderId": 9, "sellOrderId": 10, "price": 100,  "quantity": 20000}
{"buyOrderId": 6, "sellOrderId": 10, "price": 100,  "quantity": 6000}
