tests/max_peak_afrer_relaxation-or-are_queues_correctly_sorted.out
## jeżeli w linii 6 quantity=2500, to iceberg po każdej akcji ustawia sobie quantity=peak
## jeżeli w linii 3 sellOrders.id=[1,3], linii 4 sellOrders.id=[1,3,4], linii 5 sellOrders.id=[1,3,4], ale wartości są poprawne, to sortowanie sellOrders jest odwrotne względem price, ale stabline
{"buyOrders": [], "sellOrders": [{"id": 1, "price": 101, "quantity": 20000}]}
{"buyOrders": [{"id": 2, "price": 99, "quantity": 50000}], "sellOrders": [{"id": 1, "price": 101, "quantity": 20000}]}
{"buyOrders": [{"id": 2, "price": 99, "quantity": 50000}], "sellOrders": [{"id": 3, "price": 100, "quantity": 10000}, {"id": 1, "price": 101, "quantity": 20000}]}
{"buyOrders": [{"id": 2, "price": 99, "quantity": 50000}], "sellOrders": [{"id": 3, "price": 100, "quantity": 10000}, {"id": 4, "price": 100, "quantity": 7500}, {"id": 1, "price": 101, "quantity": 20000}]}
{"buyOrders": [{"id": 2, "price": 99, "quantity": 50000}, {"id": 5, "price": 98, "quantity": 25500}], "sellOrders": [{"id": 3, "price": 100, "quantity": 10000}, {"id": 4, "price": 100, "quantity": 7500}, {"id": 1, "price": 101, "quantity": 20000}]}
# ------
{"buyOrders": [{"id": 6, "price": 100, "quantity": 10000}, {"id": 2, "price": 99, "quantity": 50000}, {"id": 5, "price": 98, "quantity": 25500}], "sellOrders": [{"id": 1, "price": 101, "quantity": 20000}]}
{"buyOrderId": 6, "sellOrderId": 3, "price": 100, "quantity": 10000}
{"buyOrderId": 6, "sellOrderId": 4, "price": 100, "quantity": 7500}
# id: 6 actual quantity=100000 - 10000 - 7500
# ------
#
# ------
{"buyOrders": [{"id": 6, "price": 100, "quantity": 10000}, {"id": 2, "price": 99, "quantity": 50000}, {"id": 5, "price": 98, "quantity": 25500}], "sellOrders": [{"id": 1, "price": 101, "quantity": 20000}]}
{"buyOrderId": 6, "sellOrderId": 7, "price": 100, "quantity": 10000}
# id: 6 actual quantity=100000 - 10000 - 7500 - 10000
# ------
#
# ------
{"buyOrders": [{"id": 6, "price": 100, "quantity": 9000}, {"id": 2, "price": 99, "quantity": 50000}, {"id": 5, "price": 98, "quantity": 25500}], "sellOrders": [{"id": 1, "price": 101, "quantity": 20000}]}
{"buyOrderId": 6, "sellOrderId": 8, "price": 100, "quantity": 10000}
# id: 6 actual quantity=100000 - 10000 - 7500 - 10000 - 10000
{"buyOrderId": 6, "sellOrderId": 8, "price": 100, "quantity": 1000}
# id: 6 actual quantity=100000 - 10000 - 7500 - 10000 - 10000 - 1000
# ------
#
{"buyOrders": [{"id": 6, "price": 100, "quantity": 9000}, {"id": 9, "price": 100, "quantity": 20000}, {"id": 2, "price": 99, "quantity": 50000}, {"id": 5, "price": 98, "quantity": 25500}], "sellOrders": [{"id": 1, "price": 101, "quantity": 20000}]}
#
# ------
{"buyOrders": [{"id": 6, "price": 100, "quantity": 4000}, {"id": 9, "price": 100, "quantity": 20000}, {"id": 2, "price": 99, "quantity": 50000}, {"id": 5, "price": 98, "quantity": 25500}], "sellOrders": [{"id": 1, "price": 101, "quantity": 20000}]}
# use the newest BUY order
{"buyOrderId": 6, "sellOrderId": 10, "price": 100, "quantity": 9000}
{"buyOrderId": 9, "sellOrderId": 10, "price": 100, "quantity": 20000}
{"buyOrderId": 6, "sellOrderId": 10, "price": 100, "quantity": 6000}
